Workbook

Sheet sheetOne
A1: Chi nhánh | B1: Mã hóa đơn | D1: Thời gian | E1: Mã khách hàng | F1: Ghi chú | G1: Giảm giá hóa đơn | H1: tổng thanh toán | I1: Mã hàng | J1: IMEI | K1: Số lượng | L1: Đơn giá | M1: Giảm giá hàng hóa | N1: Giá bán | O1: Thành tiền hàng hóa
A2: HN - 10 HÀNG BÚN - KHO 1 | B2: HD001584 | C2: =vlookup(B2,'Trang tính1'!AB:AB,1,0) -> #N/A | D2: 43465.836 | E2: KH002097 | G2: 0 | H2: 9000000 | I2: PHUKIENTT{DEL1} | K2: 1 | L2: 0 | M2: 0 | N2: 0 | O2: 0
A3: HN - 10 HÀNG BÚN - KHO 1 | B3: HD001584 | C3: =vlookup(B3,'Trang tính1'!AB:AB,1,0) -> #N/A | D3: 43465.836 | E3: KH002097 | G3: 0 | H3: 9000000 | I3: ip7ph128 | J3: 359176072121804 | K3: 1 | L3: 12990000 | M3: 3990000 | N3: 9000000 | O3: 9000000
A4: HN - 10 HÀNG BÚN - KHO 1 | B4: HD001583 | C4: =vlookup(B4,'Trang tính1'!AB:AB,1,0) -> #N/A | D4: 43465.816 | E4: KH002096 | G4: 0 | H4: 5190000 | I4: PHUKIENTT{DEL1} | K4: 1 | L4: 0 | M4: 0 | N4: 0 | O4: 0
A5: HN - 10 HÀNG BÚN - KHO 1 | B5: HD001583 | C5: =vlookup(B5,'Trang tính1'!AB:AB,1,0) -> #N/A | D5: 43465.816 | E5: KH002096 | G5: 0 | H5: 5190000 | I5: ip6pd16 | J5: 354441066237841 | K5: 1 | L5: 5590000 | M5: 400000 | N5: 5190000 | O5: 5190000
A6: HN - 10 HÀNG BÚN - KHO 1 | B6: HD001582 | C6: =vlookup(B6,'Trang tính1'!AB:AB,1,0) -> HD001582 | D6: 43465.809 | G6: 0 | H6: 600000 | I6: SP000011{DEL} | K6: 1 | L6: 600000 | M6: 0 | N6: 600000 | O6: 600000
A7: HN - 10 HÀNG BÚN - KHO 1 | B7: HD001581 | C7: =vlookup(B7,'Trang tính1'!AB:AB,1,0) -> HD001581 | D7: 43465.807 | E7: KH002095 | G7: 0 | H7: 30090000 | I7: iPxsmv256 | J7: 357278099742810 | K7: 1 | L7: 30090000 | M7: 0 | N7: 30090000 | O7: 30090000
A8: HN - 10 HÀNG BÚN - KHO 1 | B8: HD001580 | C8: =vlookup(B8,'Trang tính1'!AB:AB,1,0) -> HD001580 | D8: 43465.718 | G8: 0 | H8: 400000 | I8: SP000006{DEL} | K8: 1 | L8: 400000 | M8: 0 | N8: 400000 | O8: 400000
A9: HN - 10 HÀNG BÚN - KHO 1 | B9: HD001579 | C9: =vlookup(B9,'Trang tính1'!AB:AB,1,0) -> #N/A | D9: 43465.691 | E9: KH002094 | G9: 0 | H9: 14290000 | I9: PHUKIENTG{DEL1} | K9: 1 | L9: 0 | M9: 0 | N9: 0 | O9: 0
A10: HN - 10 HÀNG BÚN - KHO 1 | B10: HD001579 | C10: =vlookup(B10,'Trang tính1'!AB:AB,1,0) -> #N/A | D10: 43465.691 | E10: KH002094 | G10: 0 | H10: 14290000 | I10: 99%ip8plusSilver64 | J10: 356768089013421 | K10: 1 | L10: 15290000 | M10: 1000000 | N10: 14290000 | O10: 14290000
A11: HN - 10 HÀNG BÚN - KHO 1 | B11: HD001578 | C11: =vlookup(B11,'Trang tính1'!AB:AB,1,0) -> #N/A | D11: 43465.647 | E11: KH000129 | G11: 0 | H11: 6100000 | I11: PHUKIENTT{DEL1} | K11: 1 | L11: 0 | M11: 0 | N11: 0 | O11: 0
A12: HN - 10 HÀNG BÚN - KHO 1 | B12: HD001578 | C12: =vlookup(B12,'Trang tính1'!AB:AB,1,0) -> #N/A | D12: 43465.647 | E12: KH000129 | G12: 0 | H12: 6100000 | I12: ip7t32 | J12: 353826081535057 | K12: 1 | L12: 8190000 | M12: 2090000 | N12: 6100000 | O12: 6100000
A13: HN - 10 HÀNG BÚN - KHO 1 | B13: HD001577 | C13: =vlookup(B13,'Trang tính1'!AB:AB,1,0) -> HD001577 | D13: 43465.623 | E13: KH002093 | G13: 0 | H13: 26790000 | I13: care1{DEL} | K13: 1 | L13: 1000000 | M13: 0 | N13: 1000000 | O13: 1000000
A14: HN - 10 HÀNG BÚN - KHO 1 | B14: HD001577 | C14: =vlookup(B14,'Trang tính1'!AB:AB,1,0) -> HD001577 | D14: 43465.623 | E14: KH002093 | G14: 0 | H14: 26790000 | I14: SP000090 | K14: 1 | L14: 200000 | M14: 0 | N14: 200000 | O14: 200000
A15: HN - 10 HÀNG BÚN - KHO 1 | B15: HD001577 | C15: =vlookup(B15,'Trang tính1'!AB:AB,1,0) -> HD001577 | D15: 43465.623 | E15: KH002093 | G15: 0 | H15: 26790000 | I15: iPxsmd64 | J15: 357269096879267 | K15: 1 | L15: 25590000 | M15: 0 | N15: 25590000 | O15: 25590000
A16: HN - 10 HÀNG BÚN - KHO 1 | B16: HD001576 | C16: =vlookup(B16,'Trang tính1'!AB:AB,1,0) -> HD001576 | D16: 43465.613 | G16: 0 | H16: 100000 | I16: SP000090 | K16: 1 | L16: 100000 | M16: 0 | N16: 100000 | O16: 100000
A17: HN - 10 HÀNG BÚN - KHO 1 | B17: HD001575 | C17: =vlookup(B17,'Trang tính1'!AB:AB,1,0) -> HD001575 | D17: 43465.6 | E17: KH000840 | G17: 0 | H17: 30790000 | I17: care1{DEL} | K17: 1 | L17: 1000000 | M17: 0 | N17: 1000000 | O17: 1000000
A18: HN - 10 HÀNG BÚN - KHO 1 | B18: HD001575 | C18: =vlookup(B18,'Trang tính1'!AB:AB,1,0) -> HD001575 | D18: 43465.6 | E18: KH000840 | G18: 0 | H18: 30790000 | I18: iPxsmt512 | J18: 357264093239508 | K18: 1 | L18: 29790000 | M18: 0 | N18: 29790000 | O18: 29790000
A19: HN - 10 HÀNG BÚN - KHO 1 | B19: HD001574 | C19: =vlookup(B19,'Trang tính1'!AB:AB,1,0) -> HD001574 | D19: 43465.515 | G19: 0 | H19: 200000 | I19: SP000090 | K19: 1 | L19: 200000 | M19: 0 | N19: 200000 | O19: 200000
A20: HN - 10 HÀNG BÚN - KHO 1 | B20: HD001573 | C20: =vlookup(B20,'Trang tính1'!AB:AB,1,0) -> HD001573 | D20: 43465.49 | E20: KH002031 | G20: 0 | H20: 29790000 | I20: iPxsmt512 | J20: 357271093044515 | K20: 1 | L20: 29790000 | M20: 0 | N20: 29790000 | O20: 29790000
A21: HN - 10 HÀNG BÚN - KHO 1 | B21: HD001571 | C21: =vlookup(B21,'Trang tính1'!AB:AB,1,0) -> HD001571 | D21: 43465.464 | E21: KH001401 | G21: 100000 | H21: 29900000 | I21: SP000090 | K21: 1 | L21: 0 | M21: 0 | N21: 0 | O21: 0
A22: HN - 10 HÀNG BÚN - KHO 1 | B22: HD001571 | C22: =vlookup(B22,'Trang tính1'!AB:AB,1,0) -> HD001571 | D22: 43465.464 | E22: KH001401 | G22: 100000 | H22: 29900000 | I22: iPxsmt512 | J22: 357263093013269 | K22: 1 | L22: 30000000 | M22: 0 | N22: 30000000 | O22: 30000000
A23: HN - 10 HÀNG BÚN - KHO 1 | B23: HD001570 | C23: =vlookup(B23,'Trang tính1'!AB:AB,1,0) -> #N/A | D23: 43465.462 | E23: KH002092 | G23: 200000 | H23: 16000000 | I23: PHUKIENTT{DEL1} | K23: 1 | L23: 0 | M23: 0 | N23: 0 | O23: 0
A24: HN - 10 HÀNG BÚN - KHO 1 | B24: HD001570 | C24: =vlookup(B24,'Trang tính1'!AB:AB,1,0) -> #N/A | D24: 43465.462 | E24: KH002092 | G24: 200000 | H24: 16000000 | I24: 99%ipxGray64 | J24: 356726083637058 | K24: 1 | L24: 16200000 | M24: 0 | N24: 16200000 | O24: 16200000
A25: HN - 10 HÀNG BÚN - KHO 1 | B25: HD001569 | C25: =vlookup(B25,'Trang tính1'!AB:AB,1,0) -> HD001569 | D25: 43465.462 | E25: KH002092 | G25: 200000 | H25: 11600000 | I25: SP000108{DEL} | J25: FH7XP662KDH0 | K25: 1 | L25: 11800000 | M25: 0 | N25: 11800000 | O25: 11800000
A26: HN - 10 HÀNG BÚN - KHO 1 | B26: HD001566 | C26: =vlookup(B26,'Trang tính1'!AB:AB,1,0) -> HD001566 | D26: 43465.408 | E26: KH000073 | G26: 0 | H26: 28200000 | I26: SP000104 | J26: FVFXF29HJK7F | K26: 1 | L26: 28200000 | M26: 0 | N26: 28200000 | O26: 28200000
A27: HN - 10 HÀNG BÚN - KHO 1 | B27: HD001565 | C27: =vlookup(B27,'Trang tính1'!AB:AB,1,0) -> HD001565 | D27: 43464.78 | E27: KH000340 | G27: 0 | H27: 200000 | I27: SP000090 | K27: 1 | L27: 200000 | M27: 0 | N27: 200000 | O27: 200000
A28: HN - 10 HÀNG BÚN - KHO 1 | B28: HD001564 | C28: =vlookup(B28,'Trang tính1'!AB:AB,1,0) -> HD001564 | D28: 43464.718 | E28: KH002091 | G28: 0 | H28: 16090000 | I28: 99%ipxSilver256cu | J28: 359409082297375 | K28: 1 | L28: 16090000 | M28: 0 | N28: 16090000 | O28: 16090000
A29: HN - 10 HÀNG BÚN - KHO 1 | B29: HD001563 | C29: =vlookup(B29,'Trang tính1'!AB:AB,1,0) -> HD001563 | D29: 43464.666 | E29: KH000396 | G29: 0 | H29: 700000 | I29: SP000106 | K29: 1 | L29: 700000 | M29: 0 | N29: 700000 | O29: 700000
A30: HN - 10 HÀNG BÚN - KHO 1 | B30: HD001562 | C30: =vlookup(B30,'Trang tính1'!AB:AB,1,0) -> HD001562 | D30: 43464.618 | E30: KH001427{DEL1} | G30: 0 | H30: 12450000 | I30: 99%ip8plusGold64 | J30: 356774088084835 | K30: 1 | L30: 15290000 | M30: 2840000 | N30: 12450000 | O30: 12450000
A31: HN - 10 HÀNG BÚN - KHO 1 | B31: HD001561 | C31: =vlookup(B31,'Trang tính1'!AB:AB,1,0) -> #N/A | D31: 43464.615 | E31: KH002090 | G31: 90000 | H31: 4000000 | I31: PHUKIENTT{DEL1} | K31: 1 | L31: 0 | M31: 0 | N31: 0 | O31: 0
A32: HN - 10 HÀNG BÚN - KHO 1 | B32: HD001561 | C32: =vlookup(B32,'Trang tính1'!AB:AB,1,0) -> #N/A | D32: 43464.615 | E32: KH002090 | G32: 90000 | H32: 4000000 | I32: ip6v64 | J32: 358363061768560 | K32: 1 | L32: 4390000 | M32: 300000 | N32: 4090000 | O32: 4090000
A33: HN - 10 HÀNG BÚN - KHO 1 | B33: HD001560 | C33: =vlookup(B33,'Trang tính1'!AB:AB,1,0) -> HD001560 | D33: 43464.583 | E33: KH002089 | G33: 0 | H33: 28580000 | I33: iPxsmv64 | J33: 357271096993759 | K33: 1 | L33: 27490000 | M33: 0 | N33: 27490000 | O33: 27490000
A34: HN - 10 HÀNG BÚN - KHO 1 | B34: HD001560 | C34: =vlookup(B34,'Trang tính1'!AB:AB,1,0) -> HD001560 | D34: 43464.583 | E34: KH002089 | G34: 0 | H34: 28580000 | I34: care1{DEL} | K34: 1 | L34: 1000000 | M34: 10000 | N34: 990000 | O34: 990000
A35: HN - 10 HÀNG BÚN - KHO 1 | B35: HD001560 | C35: =vlookup(B35,'Trang tính1'!AB:AB,1,0) -> HD001560 | D35: 43464.583 | E35: KH002089 | G35: 0 | H35: 28580000 | I35: SP000090 | K35: 1 | L35: 100000 | M35: 0 | N35: 100000 | O35: 100000
A36: HN - 10 HÀNG BÚN - KHO 1 | B36: HDD_TH000111 | C36: =vlookup(B36,'Trang tính1'!AB:AB,1,0) -> HDD_TH000111 | D36: 43464.566 | E36: KH002076 | G36: 0 | H36: 0 | I36: 99%ipxSilver256cu | J36: 356726080743826 | K36: 1 | L36: 16490000 | M36: 0 | N36: 16490000 | O36: 16490000
A37: HN - 10 HÀNG BÚN - KHO 1 | B37: HD001559 | C37: =vlookup(B37,'Trang tính1'!AB:AB,1,0) -> #N/A | D37: 43464.549 | E37: KH002088 | G37: 0 | H37: 11300000 | I37: ip7pds128 | J37: 356572081388223 | K37: 1 | L37: 13190000 | M37: 1890000 | N37: 11300000 | O37: 11300000
A38: HN - 10 HÀNG BÚN - KHO 1 | B38: HD001559 | C38: =vlookup(B38,'Trang tính1'!AB:AB,1,0) -> #N/A | D38: 43464.549 | E38: KH002088 | G38: 0 | H38: 11300000 | I38: PHUKIENTG{DEL1} | K38: 1 | L38: 0 | M38: 0 | N38: 0 | O38: 0
A39: HN - 10 HÀNG BÚN - KHO 1 | B39: HD001558 | C39: =vlookup(B39,'Trang tính1'!AB:AB,1,0) -> HD001558 | D39: 43464.499 | E39: KH002087 | G39: 0 | H39: 13390000 | I39: 99%ip8plusSilver64 | J39: 35677008743829 | K39: 1 | L39: 15290000 | M39: 1900000 | N39: 13390000 | O39: 13390000
A40: HN - 10 HÀNG BÚN - KHO 1 | B40: HD001557 | C40: =vlookup(B40,'Trang tính1'!AB:AB,1,0) -> HD001557 | D40: 43464.478 | E40: KH002086 | G40: 0 | H40: 11500000 | I40: ip7pds128 | J40: 355356080167924 | K40: 1 | L40: 13190000 | M40: 1690000 | N40: 11500000 | O40: 11500000
...

Sheet Bản sao của sheetOne
A1: Chi nhánh | B1: Mã hóa đơn | C1: Thời gian | D1: Mã khách hàng | E1: Ghi chú | F1: Giảm giá hóa đơn | G1: tổng thanh toán | H1: Mã hàng | I1: IMEI | J1: Số lượng | K1: Đơn giá | L1: Giảm giá hàng hóa | M1: Giá bán | N1: Thành tiền hàng hóa
A2: HN - 10 HÀNG BÚN - KHO 1 | B2: HD001584 | C2: 43465.836 | D2: KH002097 | F2: 0 | G2: 9000000 | H2: PHUKIENTT{DEL1} | J2: 1 | K2: 0 | L2: 0 | M2: 0 | N2: 0
A3: HN - 10 HÀNG BÚN - KHO 1 | B3: HD001584 | C3: 43465.836 | D3: KH002097 | F3: 0 | G3: 9000000 | H3: ip7ph128 | I3: 359176072121804 | J3: 1 | K3: 12990000 | L3: 3990000 | M3: 9000000 | N3: 9000000
A4: HN - 10 HÀNG BÚN - KHO 1 | B4: HD001583 | C4: 43465.816 | D4: KH002096 | F4: 0 | G4: 5190000 | H4: PHUKIENTT{DEL1} | J4: 1 | K4: 0 | L4: 0 | M4: 0 | N4: 0
A5: HN - 10 HÀNG BÚN - KHO 1 | B5: HD001583 | C5: 43465.816 | D5: KH002096 | F5: 0 | G5: 5190000 | H5: ip6pd16 | I5: 354441066237841 | J5: 1 | K5: 5590000 | L5: 400000 | M5: 5190000 | N5: 5190000
A6: HN - 10 HÀNG BÚN - KHO 1 | B6: HD001579 | C6: 43465.691 | D6: KH002094 | F6: 0 | G6: 14290000 | H6: PHUKIENTG{DEL1} | J6: 1 | K6: 0 | L6: 0 | M6: 0 | N6: 0
A7: HN - 10 HÀNG BÚN - KHO 1 | B7: HD001579 | C7: 43465.691 | D7: KH002094 | F7: 0 | G7: 14290000 | H7: 99%ip8plusSilver64 | I7: 356768089013421 | J7: 1 | K7: 15290000 | L7: 1000000 | M7: 14290000 | N7: 14290000
A8: HN - 10 HÀNG BÚN - KHO 1 | B8: HD001578 | C8: 43465.647 | D8: KH000129 | F8: 0 | G8: 6100000 | H8: PHUKIENTT{DEL1} | J8: 1 | K8: 0 | L8: 0 | M8: 0 | N8: 0
A9: HN - 10 HÀNG BÚN - KHO 1 | B9: HD001578 | C9: 43465.647 | D9: KH000129 | F9: 0 | G9: 6100000 | H9: ip7t32 | I9: 353826081535057 | J9: 1 | K9: 8190000 | L9: 2090000 | M9: 6100000 | N9: 6100000
A10: HN - 10 HÀNG BÚN - KHO 1 | B10: HD001570 | C10: 43465.462 | D10: KH002092 | F10: 200000 | G10: 16000000 | H10: PHUKIENTT{DEL1} | J10: 1 | K10: 0 | L10: 0 | M10: 0 | N10: 0
A11: HN - 10 HÀNG BÚN - KHO 1 | B11: HD001570 | C11: 43465.462 | D11: KH002092 | F11: 200000 | G11: 16000000 | H11: 99%ipxGray64 | I11: 356726083637058 | J11: 1 | K11: 16200000 | L11: 0 | M11: 16200000 | N11: 16200000
A12: HN - 10 HÀNG BÚN - KHO 1 | B12: HD001561 | C12: 43464.615 | D12: KH002090 | F12: 90000 | G12: 4000000 | H12: PHUKIENTT{DEL1} | J12: 1 | K12: 0 | L12: 0 | M12: 0 | N12: 0
A13: HN - 10 HÀNG BÚN - KHO 1 | B13: HD001561 | C13: 43464.615 | D13: KH002090 | F13: 90000 | G13: 4000000 | H13: ip6v64 | I13: 358363061768560 | J13: 1 | K13: 4390000 | L13: 300000 | M13: 4090000 | N13: 4090000
A14: HN - 10 HÀNG BÚN - KHO 1 | B14: HD001559 | C14: 43464.549 | D14: KH002088 | F14: 0 | G14: 11300000 | H14: ip7pds128 | I14: 356572081388223 | J14: 1 | K14: 13190000 | L14: 1890000 | M14: 11300000 | N14: 11300000
A15: HN - 10 HÀNG BÚN - KHO 1 | B15: HD001559 | C15: 43464.549 | D15: KH002088 | F15: 0 | G15: 11300000 | H15: PHUKIENTG{DEL1} | J15: 1 | K15: 0 | L15: 0 | M15: 0 | N15: 0
A16: HN - 10 HÀNG BÚN - KHO 1 | B16: HD001554 | C16: 43463.682 | D16: KH002084 | F16: 90000 | G16: 6900000 | H16: ip7ds128 | I16: 353826080284202 | J16: 1 | K16: 9190000 | L16: 2200000 | M16: 6990000 | N16: 6990000
A17: HN - 10 HÀNG BÚN - KHO 1 | B17: HD001554 | C17: 43463.682 | D17: KH002084 | F17: 90000 | G17: 6900000 | H17: PHUKIENTT{DEL1} | J17: 1 | K17: 0 | L17: 0 | M17: 0 | N17: 0
A18: HN - 10 HÀNG BÚN - KHO 1 | B18: HD001553 | C18: 43463.66 | D18: KH002083 | F18: 90000 | G18: 7600000 | H18: SP000028{DEL} | J18: 1 | K18: 500000 | L18: 200000 | M18: 300000 | N18: 300000
A19: HN - 10 HÀNG BÚN - KHO 1 | B19: HD001553 | C19: 43463.66 | D19: KH002083 | F19: 90000 | G19: 7600000 | H19: PHUKIENTT{DEL1} | J19: 1 | K19: 0 | L19: 0 | M19: 0 | N19: 0
A20: HN - 10 HÀNG BÚN - KHO 1 | B20: HD001553 | C20: 43463.66 | D20: KH002083 | F20: 90000 | G20: 7600000 | H20: ip6sph64 | I20: 35333107235553 | J20: 1 | K20: 8390000 | L20: 1000000 | M20: 7390000 | N20: 7390000
A21: HN - 10 HÀNG BÚN - KHO 1 | B21: HD001545 | C21: 43462.783 | D21: KH002079 | F21: 0 | G21: 14890000 | H21: PHUKIENTG{DEL1} | J21: 1 | K21: 0 | L21: 0 | M21: 0 | N21: 0
A22: HN - 10 HÀNG BÚN - KHO 1 | B22: HD001545 | C22: 43462.783 | D22: KH002079 | F22: 0 | G22: 14890000 | H22: 99%ip8plusGold64 | I22: 354834091580435 | J22: 1 | K22: 15290000 | L22: 400000 | M22: 14890000 | N22: 14890000
A23: HN - 10 HÀNG BÚN - KHO 1 | B23: HD001538 | C23: 43462.504 | D23: KH002076 | F23: 0 | G23: 16490000 | H23: PHUKIENTT{DEL1} | J23: 1 | K23: 0 | L23: 0 | M23: 0 | N23: 0
A24: HN - 10 HÀNG BÚN - KHO 1 | B24: HD001538 | C24: 43462.504 | D24: KH002076 | F24: 0 | G24: 16490000 | H24: 99%ipxSilver256cu | I24: 356726089144646 | J24: 1 | K24: 16490000 | L24: 0 | M24: 16490000 | N24: 16490000
A25: HN - 10 HÀNG BÚN - KHO 1 | B25: HD001530 | C25: 43461.711 | D25: KH002074 | F25: 200000 | G25: 11090000 | H25: ip7pds256 | I25: 355356081953231 | J25: 1 | K25: 13290000 | L25: 2000000 | M25: 11290000 | N25: 11290000
A26: HN - 10 HÀNG BÚN - KHO 1 | B26: HD001530 | C26: 43461.711 | D26: KH002074 | F26: 200000 | G26: 11090000 | H26: PHUKIENTT{DEL1} | J26: 1 | K26: 0 | L26: 0 | M26: 0 | N26: 0
A27: HN - 10 HÀNG BÚN - KHO 1 | B27: HD001526 | C27: 43460.867 | D27: KH002072 | F27: 0 | G27: 15990000 | H27: PHUKIENTT{DEL1} | J27: 1 | K27: 0 | L27: 0 | M27: 0 | N27: 0
A28: HN - 10 HÀNG BÚN - KHO 1 | B28: HD001526 | C28: 43460.867 | D28: KH002072 | F28: 0 | G28: 15990000 | H28: 99%ipxSilver64cu | I28: 359410081799346 | J28: 1 | K28: 15990000 | L28: 0 | M28: 15990000 | N28: 15990000
A29: HN - 10 HÀNG BÚN - KHO 1 | B29: HD001525 | C29: 43460.818 | D29: KH002070 | F29: 0 | G29: 11890000 | H29: PHUKIENTG{DEL1} | J29: 1 | K29: 0 | L29: 0 | M29: 0 | N29: 0
A30: HN - 10 HÀNG BÚN - KHO 1 | B30: HD001525 | C30: 43460.818 | D30: KH002070 | F30: 0 | G30: 11890000 | H30: ip7pt128 | I30: 359215071716220 | J30: 1 | K30: 12990000 | L30: 1300000 | M30: 11690000 | N30: 11690000
A31: HN - 10 HÀNG BÚN - KHO 1 | B31: HD001525 | C31: 43460.818 | D31: KH002070 | F31: 0 | G31: 11890000 | H31: Jachchuyendoi{DEL} | J31: 1 | K31: 200000 | L31: 0 | M31: 200000 | N31: 200000
A32: HN - 10 HÀNG BÚN - KHO 1 | B32: HD001524 | C32: 43460.581 | D32: KH002071 | F32: 0 | G32: 10690000 | H32: PHUKIENTG{DEL1} | J32: 1 | K32: 0 | L32: 0 | M32: 0 | N32: 0
A33: HN - 10 HÀNG BÚN - KHO 1 | B33: HD001524 | C33: 43460.581 | D33: KH002071 | F33: 0 | G33: 10690000 | H33: ip7pds32 | I33: 355375084182689 | J33: 1 | K33: 11490000 | L33: 800000 | M33: 10690000 | N33: 10690000
A34: HN - 10 HÀNG BÚN - KHO 1 | B34: HD001519 | C34: 43459.778 | D34: KH002068 | F34: 0 | G34: 2490000 | H34: ip5sd16 | I34: 352001068660242 | J34: 1 | K34: 2490000 | L34: 0 | M34: 2490000 | N34: 2490000
A35: HN - 10 HÀNG BÚN - KHO 1 | B35: HD001519 | C35: 43459.778 | D35: KH002068 | F35: 0 | G35: 2490000 | H35: PHUKIENTT{DEL1} | J35: 1 | K35: 0 | L35: 0 | M35: 0 | N35: 0
A36: HN - 10 HÀNG BÚN - KHO 1 | B36: HD001516 | C36: 43459.687 | D36: KH002066 | F36: 200000 | G36: 10490000 | H36: PHUKIENTG{DEL1} | J36: 1 | K36: 0 | L36: 0 | M36: 0 | N36: 0
A37: HN - 10 HÀNG BÚN - KHO 1 | B37: HD001516 | C37: 43459.687 | D37: KH002066 | F37: 200000 | G37: 10490000 | H37: ip7pds32 | I37: 359174074776089 | J37: 1 | K37: 11490000 | L37: 800000 | M37: 10690000 | N37: 10690000
A38: HN - 10 HÀNG BÚN - KHO 1 | B38: HD001515 | C38: 43459.677 | D38: KH002065 | F38: 0 | G38: 10700000 | H38: PHUKIENTG{DEL1} | J38: 1 | K38: 0 | L38: 0 | M38: 0 | N38: 0
A39: HN - 10 HÀNG BÚN - KHO 1 | B39: HD001515 | C39: 43459.677 | D39: KH002065 | F39: 0 | G39: 10700000 | H39: ip7pds32 | I39: 353819089012682 | J39: 1 | K39: 11490000 | L39: 790000 | M39: 10700000 | N39: 10700000
A40: HN - 10 HÀNG BÚN - KHO 1 | B40: HD001509 | C40: 43459.469 | D40: KH002063 | F40: 0 | G40: 10990000 | H40: ip7ph32 | I40: 353814080258749 | J40: 1 | K40: 11190000 | L40: 200000 | M40: 10990000 | N40: 10990000
...

Sheet Trang tính1
A1: 43286.646 | B1: 43286.646 | C1: 10HB-2503016510 | D1: IPADMINID32 | E1: IPadmini | F1: iPad>>IPad | G1: Chiếc | J1: 358774053580856 | K1: 1 | L1: 5000000 | M1: 5000000 | N1: 0 | O1: 5000000 | Y1: 10HB | Z1: HN - 10 HÀNG BÚN - KHO 1 | AB1: HD000067
A2: 43286.646 | B2: 43286.646 | C2: 10HB-2503016509 | D2: IP8PDO64NEW | E2: iphone 8-plus - đỏ - 64gb - new | G2: Chiếc | J2: 353011099532905 | K2: 1 | L2: 19590000 | M2: 19590000 | N2: 290000 | O2: 19300000 | R2: KH000946 | S2: Anh Sang | U2: 0968333332 | Y2: 10HB | Z2: HN - 10 HÀNG BÚN - KHO 1 | AB2: HD000068
A3: 43286.648 | B3: 43286.648 | C3: 10HB-2503016507 | D3: 99%IP8PLUSGOLD256 | E3: iPhone 8 Plus 256 Gold Cũ - vàng - 256gb | G3: Chiếc | J3: 353009099091641 | K3: 1 | L3: 21500000 | M3: 21500000 | N3: 0 | O3: 21500000 | Y3: 10HB | Z3: HN - 10 HÀNG BÚN - KHO 1 | AB3: HD000070
A4: 43286.648 | B4: 43286.648 | C4: 10HB-2503016506 | D4: IPXT256NEW | E4: iphone x - trắng - 256gb - new | G4: Chiếc | J4: 354870090470699 | K4: 1 | L4: 26990000 | M4: 26990000 | N4: 0 | O4: 26990000 | R4: KH001171 | S4: Anh Tuấn bạn (A thanh Kevin) | U4: 0946969999 | Y4: 10HB | Z4: HN - 10 HÀNG BÚN - KHO 1 | AB4: HD000071
A5: 43286.649 | B5: 43286.649 | C5: 10HB-2503016504 | D5: JACHCHUYENDOI{DEL} | E5: Jach chuyển | G5: Chiếc | K5: 1 | L5: 150000 | M5: 150000 | N5: 0 | O5: 150000 | R5: 0328800347 | S5: Nguyễn Văn Long | U5: 0328800347 | Y5: 10HB | Z5: HN - 10 HÀNG BÚN - KHO 1 | AB5: HD000073
A6: 43286.651 | B6: 43286.651 | C6: 10HB-2503016503 | D6: SP000003{DEL} | E6: Sửa iPhone 6 | G6: Chiếc | K6: 1 | L6: 1600000 | M6: 1600000 | N6: 0 | O6: 1600000 | R6: KH001173 | S6: Anh Quân | U6: 0989378895 | Y6: 10HB | Z6: HN - 10 HÀNG BÚN - KHO 1 | AB6: HD000075
A7: 43286.654 | B7: 43286.654 | C7: 10HB-2503016502 | D7: IP6PD16 | E7: iphone 6 plus | F7: iPhone 6 | G7: Chiếc | J7: 354388060331726 | K7: 1 | L7: 5390000 | M7: 5390000 | N7: 490000 | O7: 4900000 | Y7: 10HB | Z7: HN - 10 HÀNG BÚN - KHO 1 | AB7: HD000076
A8: 43286.658 | B8: 43286.658 | C8: 10HB-2503016496 | D8: CUSAC ZIN{DEL} | E8: Củ Sạc Zin | G8: Chiếc | K8: 1 | L8: 250000 | M8: 250000 | N8: 0 | O8: 250000 | R8: 0328800347 | S8: Nguyễn Văn Long | U8: 0328800347 | Y8: 10HB | Z8: HN - 10 HÀNG BÚN - KHO 1 | AB8: HD000083
A9: 43286.658 | B9: 43286.658 | C9: 10HB-2503016496 | D9: DAYSAC{DEL} | E9: Dây Sạc | G9: Chiếc | K9: 1 | L9: 100000 | M9: 100000 | N9: 0 | O9: 100000 | R9: 0328800347 | S9: Nguyễn Văn Long | U9: 0328800347 | Y9: 10HB | Z9: HN - 10 HÀNG BÚN - KHO 1 | AB9: HD000083
A10: 43286.66 | B10: 43286.66 | C10: 10HB-2503016494 | D10: CHAYPHANMEEM | E10: Chạy Phần Mềm | G10: Chiếc | K10: 1 | L10: 200000 | M10: 200000 | N10: 0 | O10: 200000 | R10: 0328800347 | S10: Nguyễn Văn Long | U10: 0328800347 | Y10: 10HB | Z10: HN - 10 HÀNG BÚN - KHO 1 | AB10: HD000085
A11: 43286.661 | B11: 43286.661 | C11: 10HB-2503016493 | D11: IP7PV128CPO{DEL} | E11: iPhone 7 Plus CPO - vàng - 128gb | G11: Chiếc | J11: 359469083724538 | K11: 1 | L11: 17000000 | M11: 17000000 | N11: 0 | O11: 17000000 | R11: KH001177 | S11: Anh Thắng | U11: 0329312516 | Y11: 10HB | Z11: HN - 10 HÀNG BÚN - KHO 1 | AB11: HD000086
A12: 43286.661 | B12: 43286.661 | C12: 10HB-2503016492 | D12: IP7PT32 | E12: iphone 7 plus | F12: iPhone 7 | G12: Chiếc | J12: 353820083101018 | K12: 1 | L12: 11390000 | M12: 11390000 | N12: 790000 | O12: 10600000 | Y12: 10HB | Z12: HN - 10 HÀNG BÚN - KHO 1 | AB12: HD000087
A13: 43286.663 | B13: 43286.663 | C13: 10HB-2503016489 | D13: IP7PH128CPO{DEL} | E13: iPhone 7 Plus CPO - hồng - 128gb | G13: Chiếc | J13: 356694089011241 | K13: 1 | L13: 16300000 | M13: 16300000 | N13: 0 | O13: 16300000 | R13: KH000102 | S13: Altis Anh Duy | U13: 0988099965 | Y13: 10HB | Z13: HN - 10 HÀNG BÚN - KHO 1 | AB13: HD000090
A14: 43286.751 | B14: 43286.751 | C14: 10HB-2503016486 | D14: SP000009{DEL} | E14: PIN iP5s | G14: Chiếc | K14: 1 | L14: 300000 | M14: 300000 | N14: 0 | O14: 300000 | R14: KH001179 | S14: Chị Giang | U14: 0945359397 | Y14: 10HB | Z14: HN - 10 HÀNG BÚN - KHO 1 | AB14: HD000095
A15: 43286.849 | B15: 43286.849 | C15: 10HB-2503016483 | D15: SP000007{DEL} | E15: PIN iP6s Plus | G15: Chiếc | K15: 7 | L15: 0 | M15: 0 | N15: 0 | O15: 0 | R15: KH001182 | S15: Thay pin ( 7 cây 6splus ) 111111 | U15: 0900000036 | Y15: 10HB | Z15: HN - 10 HÀNG BÚN - KHO 1 | AB15: HD000099
A16: 43287.449 | B16: 43287.449 | C16: 10HB-2503016481 | D16: SP000011{DEL} | E16: Sửa Home iP6 Plus | G16: Chiếc | K16: 1 | L16: 250000 | M16: 250000 | N16: 0 | O16: 250000 | R16: KH000945 | S16: Cô Huế ( Người Nhà A Táo ). | U16: 0983938229 | Y16: 10HB | Z16: HN - 10 HÀNG BÚN - KHO 1 | AB16: HD000101
A17: 43287.473 | B17: 43287.473 | C17: 10HB-2503016480 | D17: SP000005{DEL} | E17: PIN iP6s | G17: Chiếc | K17: 1 | L17: 350000 | M17: 350000 | N17: 0 | O17: 350000 | R17: KH001184 | S17: Bạn Cương | U17: 0974792228 | Y17: 10HB | Z17: HN - 10 HÀNG BÚN - KHO 1 | AA17: imel : 447313 | AB17: HD000102
A18: 43287.735 | B18: 43287.735 | C18: 10HB-2503016475 | D18: DAYSAC{DEL} | E18: Dây Sạc | G18: Chiếc | K18: 1 | L18: 100000 | M18: 100000 | N18: 0 | O18: 100000 | R18: 0328800347 | S18: Nguyễn Văn Long | U18: 0328800347 | Y18: 10HB | Z18: HN - 10 HÀNG BÚN - KHO 1 | AB18: HD000108
A19: 43288.514 | B19: 43288.514 | C19: 10HB-2503016472 | D19: IP7DS128 | E19: iphone 7 | F19: iPhone 7 | G19: Chiếc | J19: 359162074860565 | K19: 1 | L19: 9990000 | M19: 9990000 | N19: 1690000 | O19: 8300000 | R19: KH000454 | S19: A Hải | U19: 0906051443 | Y19: 10HB | Z19: HN - 10 HÀNG BÚN - KHO 1 | AB19: HD000112
A20: 43288.609 | B20: 43288.609 | C20: 10HB-2503016471 | D20: 99%IPXSILVER256CU | E20: iPhone X 256 Silver Cũ | F20: iPhone Cũ 99% | G20: Chiếc | J20: 353046094337421 | K20: 1 | L20: 20500000 | M20: 20500000 | N20: 0 | O20: 20500000 | Y20: 10HB | Z20: HN - 10 HÀNG BÚN - KHO 1 | AB20: HD000113
A21: 43288.631 | B21: 43288.631 | C21: 10HB-2503016470 | D21: IPXD64NEW | E21: iphone x - đen - 64gb - new | G21: Chiếc | J21: 353043092464943 | K21: 1 | L21: 25000000 | M21: 25000000 | N21: 0 | O21: 25000000 | R21: KH001293 | S21: (VIP) Anh Khôi( Chồng Chị Lan Hair). | U21: 0902188888 | Y21: 10HB | Z21: HN - 10 HÀNG BÚN - KHO 1 | AB21: HD000114
A22: 43288.812 | B22: 43288.812 | C22: 10HB-2503016469 | D22: IPADMINI2WIFI4G16GB | E22: iPadmini | F22: iPad>>IPad | G22: Chiếc | J22: 358775053081639 | K22: 1 | L22: 3500000 | M22: 3500000 | N22: 0 | O22: 3500000 | R22: KH001294 | S22: Chị Tuyết | U22: 0904780242 | Y22: 10HB | Z22: HN - 10 HÀNG BÚN - KHO 1 | AB22: HD000115
A23: 43289.487 | B23: 43289.487 | C23: 10HB-2503016467 | D23: IP7DS128 | E23: iphone 7 | F23: iPhone 7 | G23: Chiếc | J23: 353922082729591 | K23: 1 | L23: 9990000 | M23: 9990000 | N23: 1890000 | O23: 8100000 | Y23: 10HB | Z23: HN - 10 HÀNG BÚN - KHO 1 | AB23: HD000118
A24: 43289.494 | B24: 43289.494 | C24: 10HB-2503016466 | D24: SP000013{DEL} | E24: Thay Man iP6 | G24: Chiếc | K24: 1 | L24: 900000 | M24: 900000 | N24: 0 | O24: 900000 | R24: 0328800347 | S24: Nguyễn Văn Long | U24: 0328800347 | Y24: 10HB | Z24: HN - 10 HÀNG BÚN - KHO 1 | AB24: HD000119
A25: 43290.468 | B25: 43290.468 | C25: 10HB-2503016465 | D25: IPXT256NEW | E25: iphone x - trắng - 256gb - new | G25: Chiếc | J25: 359407089783892 | K25: 1 | L25: 27400000 | M25: 27400000 | N25: 100000 | O25: 27300000 | R25: KH001296 | S25: Chị Nguyễn Thanh Hằng | U25: 0328352861 | Y25: 10HB | Z25: HN - 10 HÀNG BÚN - KHO 1 | AB25: HD000121
A26: 43290.682 | B26: 43290.682 | C26: 10HB-2503016462 | D26: SP000014{DEL} | E26: ipad mini 4 | G26: Chiếc | J26: 359275065669223 | K26: 1 | L26: 10000000 | M26: 10000000 | N26: 0 | O26: 10000000 | R26: KH001299 | S26: Anh Hiếu | U26: 0966956886 | Y26: 10HB | Z26: HN - 10 HÀNG BÚN - KHO 1 | AB26: HD000124
A27: 43290.714 | B27: 43290.714 | C27: 10HB-2503016461 | D27: SP000011{DEL} | E27: Sửa Home iP6 Plus | G27: Chiếc | K27: 1 | L27: 250000 | M27: 250000 | N27: 0 | O27: 250000 | R27: 0328800347 | S27: Nguyễn Văn Long | U27: 0328800347 | Y27: 10HB | Z27: HN - 10 HÀNG BÚN - KHO 1 | AB27: HD000126
A28: 43290.754 | B28: 43290.754 | C28: 10HB-2503016460 | D28: IP6PD16 | E28: iphone 6 plus | F28: iPhone 6 | G28: Chiếc | J28: 354391063420546 | K28: 1 | L28: 5490000 | M28: 5490000 | N28: 590000 | O28: 4900000 | R28: 0328800347 | S28: Nguyễn Văn Long | U28: 0328800347 | Y28: 10HB | Z28: HN - 10 HÀNG BÚN - KHO 1 | AB28: HD000127
A29: 43290.754 | B29: 43290.754 | C29: 10HB-2503016460 | D29: IP6SPH64 | E29: iphone 6s plus | F29: iPhone 6s | G29: Chiếc | J29: 353297070632497 | K29: 1 | L29: 8390000 | M29: 8390000 | N29: 890000 | O29: 7500000 | R29: 0328800347 | S29: Nguyễn Văn Long | U29: 0328800347 | Y29: 10HB | Z29: HN - 10 HÀNG BÚN - KHO 1 | AB29: HD000127
A30: 43290.805 | B30: 43290.805 | C30: 10HB-2503016459 | D30: SP000014{DEL} | E30: ipad mini 4 | G30: Chiếc | J30: 354996070966768 | K30: 1 | L30: 10000000 | M30: 10000000 | N30: 0 | O30: 10000000 | R30: KH001300 | S30: Anh Dũng | U30: 0949813888 | Y30: 10HB | Z30: HN - 10 HÀNG BÚN - KHO 1 | AB30: HD000128
A31: 43290.812 | B31: 43290.812 | C31: 10HB-2503016458 | D31: IP6PT16 | E31: iphone 6 plus | F31: iPhone 6 | G31: Chiếc | J31: 352066062795047 | K31: 1 | L31: 5490000 | M31: 5490000 | N31: 290000 | O31: 5200000 | R31: KH001301 | S31: Em Trang | U31: 0915079717 | Y31: 10HB | Z31: HN - 10 HÀNG BÚN - KHO 1 | AB31: HD000129
A32: 43290.826 | B32: 43290.826 | C32: 10HB-2503016457 | D32: IP7PT128 | E32: iphone 7 plus | F32: iPhone 7 | G32: Chiếc | J32: 355346085187522 | K32: 1 | L32: 12990000 | M32: 12990000 | N32: 690000 | O32: 12300000 | Y32: 10HB | Z32: HN - 10 HÀNG BÚN - KHO 1 | AB32: HD000130
A33: 43290.882 | B33: 43290.882 | C33: 10HB-2503016456 | D33: 99%IPXGRAY64 | E33: iPhone X 64 Gray Cũ | F33: iPhone Cũ 99% | G33: Chiếc | J33: 353039098943310 | K33: 1 | L33: 21000000 | M33: 21000000 | N33: 0 | O33: 21000000 | R33: KH001302 | S33: Em Việt | U33: 0822982899 | Y33: 10HB | Z33: HN - 10 HÀNG BÚN - KHO 1 | AB33: HD000131
A34: 43291.484 | B34: 43291.484 | C34: 10HB-2503016455 | D34: SP000016{DEL} | E34: Thay Màn iPhone 6 Plus | G34: Chiếc | K34: 1 | L34: 1500000 | M34: 1500000 | N34: 0 | O34: 1500000 | R34: KH001303 | S34: Anh Quốc | U34: 0852299442 | Y34: 10HB | Z34: HN - 10 HÀNG BÚN - KHO 1 | AB34: HD000133
A35: 43291.57 | B35: 43291.57 | C35: 10HB-2503016454 | D35: IP8PDO64NEW | E35: iphone 8-plus - đỏ - 64gb - new | G35: Chiếc | J35: 353011099435802 | K35: 1 | L35: 19590000 | M35: 19590000 | N35: 5390000 | O35: 14200000 | Y35: 10HB | Z35: HN - 10 HÀNG BÚN - KHO 1 | AB35: HD000134
A36: 43291.648 | B36: 43291.648 | C36: 10HB-2503016453 | D36: IP8PDO64NEW | E36: iphone 8-plus - đỏ - 64gb - new | G36: Chiếc | J36: 353011099443798 | K36: 1 | L36: 19590000 | M36: 19590000 | N36: 5190000 | O36: 14400000 | Y36: 10HB | Z36: HN - 10 HÀNG BÚN - KHO 1 | AB36: HD000135
A37: 43291.743 | B37: 43291.743 | C37: 10HB-2503016452 | D37: SP000017{DEL} | E37: Ép kính iPhone 6s | G37: Chiếc | K37: 1 | L37: 400000 | M37: 400000 | N37: 0 | O37: 400000 | R37: 0328800347 | S37: Nguyễn Văn Long | U37: 0328800347 | Y37: 10HB | Z37: HN - 10 HÀNG BÚN - KHO 1 | AB37: HD000136
A38: 43291.804 | B38: 43291.804 | C38: 10HB-2503016451 | D38: IP6PV128 | E38: iphone 6 plus | F38: iPhone 6 | G38: Chiếc | J38: 352066065579273 | K38: 1 | L38: 6990000 | M38: 6990000 | N38: 490000 | O38: 6500000 | R38: KH001301 | S38: Em Trang | U38: 0915079717 | Y38: 10HB | Z38: HN - 10 HÀNG BÚN - KHO 1 | AB38: HDD_TH000006
A39: 43291.808 | B39: 43291.808 | C39: 10HB-2503016450 | D39: IP6D16 | E39: iphone 6 | F39: iPhone 6 | G39: Chiếc | J39: 355403071751454 | K39: 1 | L39: 3990000 | M39: 3990000 | N39: 290000 | O39: 3700000 | R39: KH001304 | S39: Em Tùng | U39: 0989226529 | Y39: 10HB | Z39: HN - 10 HÀNG BÚN - KHO 1 | AB39: HD000138
A40: 43291.826 | B40: 43291.826 | C40: 10HB-2503016448 | D40: 99%IPXGRAY256CU | E40: iPhone X 256 Gray Cũ | F40: iPhone Cũ 99% | G40: Chiếc | J40: 353042098037661 | K40: 1 | L40: 27000000 | M40: 27000000 | N40: 0 | O40: 27000000 | R40: KH000097 | S40: (VIP) Anh Tuấn ( Chất ) | U40: 0932558888 | Y40: 10HB | Z40: HN - 10 HÀNG BÚN - KHO 1 | AB40: HD000140
...

Sheet test
A1: HN - 10 HÀNG BÚN - KHO 1 | B1: HD003954 | C1: 45737 | D1: KH003670 | F1: 0 | G1: 10690000 | H1: care1{DEL} | J1: 1 | K1: 1000000 | L1: 300000 | M1: 700000 | N1: 700000
A2: HN - 10 HÀNG BÚN - KHO 1 | B2: HD003954 | C2: 45737 | D2: KH003670 | F2: 0 | G2: 10690000 | H2: SP000185 | I2: G99YV52WKDH4 | J2: 1 | K2: 9690000 | L2: 0 | M2: 9690000 | N2: 9690000
A3: HN - 10 HÀNG BÚN - KHO 1 | B3: HD003954 | C3: 45737 | D3: KH003670 | F3: 0 | G3: 10690000 | H3: daythepfake{DEL} | J3: 1 | K3: 300000 | L3: 0 | M3: 300000 | N3: 300000
